Workbook
Name Slicer_AC_Non_AC: #N/A
Name Slicer_Bed_Type: #N/A
Name Slicer_Check_in_Date: #N/A
Name Slicer_Check_out_date: #N/A
Name Slicer_Food_ID: #N/A
Name Slicer_Food_Type: #N/A
Name Slicer_No.of_Days: #N/A
Name Slicer_Order_Type: #N/A
Name Slicer_Price_per_day: #N/A
Name Slicer_Quantity: #N/A
Name Slicer_Room_Type: #N/A
Name Slicer_Total_Amount: #N/A

Sheet Coustmer Details
A2: Coustmer Personal details | M2: Coustmer Address Details
A3: S.no | B3: Coustmer ID | C3: First Name | D3: Last Name | E3: Candidate Name | F3: Mail ID | G3: Phone Number | H3: Gender | I3: DOB | J3: Age | K3: ID Proof | L3: ID Number | M3: Door No | N3: Street Name | O3: District Name | P3: State Name | Q3: Corresponding Address | R3: Premanent Address
A4: 1 | B4: C001 | C4: Madhu | D4: Sree | E4: =_xlfn.CONCAT(C4,D4) -> MadhuSree | F4: =_xlfn.CONCAT(E4,"C001@gmail.com") -> MadhuSreeC001@gmail.com | G4: 6301832404 | H4: Female | I4: 38461 | J4: =DATEDIF(I4,TODAY(),"Y") -> 21 | K4: Adharcard | L4: 63210458387 | M4: 501 | N4: Sevenhills Colony | O4: Anantapur | P4: Andhra Pradesh | Q4: Gooty | R4: Sevenhills Colony,Anantapur
A5: 2 | B5: C002 | C5: Divya | D5: Chandrika | E5: =_xlfn.CONCAT(C5,D5) -> DivyaChandrika | F5: =_xlfn.CONCAT(E5,"C002@gmail.com") -> DivyaChandrikaC002@gmail.com | G5: 9502991554 | H5: Female | I5: 37877 | J5: =DATEDIF(I5,TODAY(),"Y") -> 22 | K5: Adharcard | L5: 96541238078 | M5: 111 | N5: Sai Nagar | O5: Anantapur | P5: Andhra Pradesh | Q5: KalyanDurgam | R5: Sai Nagar,Anantapur
A6: 3 | B6: C003 | C6: Hima | D6: Sree | E6: =_xlfn.CONCAT(C6,D6) -> Hima Sree | F6: =_xlfn.CONCAT(E6,"C003@gmail.com") -> Hima SreeC003@gmail.com | G6: 9712358642 | H6: Female | I6: 38209 | J6: =DATEDIF(I6,TODAY(),"Y") -> 21 | K6: PANCARD | L6: AAAAA1234A | M6: 101 | N6: 2nd Cross | O6: Anantapur | P6: Andhra Pradesh | Q6: Rudrampet | R6: 2nd Cross,Anantapur
A7: 4 | B7: C004 | C7: Madhu | D7: Priya | E7: =_xlfn.CONCAT(C7,D7) -> MadhuPriya | F7: =_xlfn.CONCAT(E7,"C004@gmail.com") -> MadhuPriyaC004@gmail.com | G7: 9652343124 | H7: Female | I7: 38018 | J7: =DATEDIF(I7,TODAY(),"Y") -> 22 | K7: Adharcard | L7: 63210458387 | M7: 123 | N7: Jesus Nagar | O7: Anantapur | P7: Andhra Pradesh | Q7: Hyderabad | R7: Jesus Nagar,Anantapur
A8: 5 | B8: C005 | C8: Vishnu | D8: Priya | E8: =_xlfn.CONCAT(C8,D8) -> Vishnu Priya | F8: =_xlfn.CONCAT(E8,"C005@gmail.com") -> Vishnu PriyaC005@gmail.com | G8: 8897662119 | H8: Female | I8: 37410 | J8: =DATEDIF(I8,TODAY(),"Y") -> 23 | K8: Adharcard | L8: 96541238078 | M8: 147 | N8: Naik Nagar | O8: Anantapur | P8: Andhra Pradesh | Q8: Pamidi | R8: Naik Nagar,Anantapur
A9: 6 | B9: C006 | C9: Jaya | D9: Sree | E9: =_xlfn.CONCAT(C9,D9) -> JayaSree | F9: =_xlfn.CONCAT(E9,"C006@gmail.com") -> JayaSreeC006@gmail.com | G9: 6302449968 | H9: Female | I9: 37358 | J9: =DATEDIF(I9,TODAY(),"Y") -> 24 | K9: PANCARD | L9: CCCCC324C | M9: 851 | N9: Sai Nagar | O9: Anantapur | P9: Andhra Pradesh | Q9: Gooty | R9: Sai Nagar,Anantapur
A10: 7 | B10: C007 | C10: Ashok | D10: Kumar | E10: =_xlfn.CONCAT(C10,D10) -> AshokKumar | F10: =_xlfn.CONCAT(E10,"C007@gmail.com") -> AshokKumarC007@gmail.com | G10: 8302448877 | H10: Male | I10: 38488 | J10: =DATEDIF(I10,TODAY(),"Y") -> 21 | K10: PANCARD | L10: VACGF876B | M10: 324 | N10: KalyanDurgam Bypass | O10: Anantapur | P10: Andhra Pradesh | Q10: KalyanDurgam | R10: KalyanDurgam Bypass,Anantapur
A11: 8 | B11: C008 | C11: Uday | D11: Simha | E11: =_xlfn.CONCAT(C11,D11) -> UdaySimha | F11: =_xlfn.CONCAT(E11,"C008@gmail.com") -> UdaySimhaC008@gmail.com | G11: 6501328746 | H11: Male | I11: 37517 | J11: =DATEDIF(I11,TODAY(),"Y") -> 23 | K11: Adharcard | L11: 63210458387 | M11: 101 | N11: 1st Road | O11: Anantapur | P11: Andhra Pradesh | Q11: ChennaKothapalli | R11: 1st Road,Anantapur
A12: 9 | B12: C009 | C12: Simha | D12: Priya | E12: =_xlfn.CONCAT(C12,D12) -> SimhaPriya | F12: =_xlfn.CONCAT(E12,"C009@gmail.com") -> SimhaPriyaC009@gmail.com | G12: 9985132546 | H12: Female | I12: 36892 | J12: =DATEDIF(I12,TODAY(),"Y") -> 25 | K12: Adharcard | L12: 96541238078 | M12: 107 | N12: Jesus Nagar | O12: Anantapur | P12: Andhra Pradesh | Q12: Dharmavaram | R12: Jesus Nagar,Anantapur
A13: 10 | B13: C010 | C13: Rupa | D13: Nandhini | E13: =_xlfn.CONCAT(C13,D13) -> RupaNandhini | F13: =_xlfn.CONCAT(E13,"C010@gmail.com") -> RupaNandhiniC010@gmail.com | G13: 9876523344 | H13: Female | I13: 38234 | J13: =DATEDIF(I13,TODAY(),"Y") -> 21 | K13: PANCARD | L13: MNJJK987Y | M13: 122 | N13: HousingBoard Colony | O13: Anantapur | P13: Andhra Pradesh | Q13: Pamidi | R13: HousingBoard Colony,Anantapur
A14: 11 | B14: C011 | C14: Bhuvan | D14: Sai | E14: =_xlfn.CONCAT(C14,D14) -> BhuvanSai | F14: =_xlfn.CONCAT(E14,"C011@gmail.com") -> BhuvanSaiC011@gmail.com | G14: 6301832404 | H14: Male | I14: 38022 | J14: =DATEDIF(I14,TODAY(),"Y") -> 22 | K14: Adharcard | L14: 98745612309 | M14: 501 | N14: Sevenhills Colony | O14: Anantapur | P14: Andhra Pradesh | Q14: Gooty | R14: Sevenhills Colony,Anantapur
A15: 12 | B15: C012 | C15: Sai | D15: Kiran | E15: =_xlfn.CONCAT(C15,D15) -> SaiKiran | F15: =_xlfn.CONCAT(E15,"C012@gmail.com") -> SaiKiranC012@gmail.com | G15: 9502991554 | H15: Male | I15: 38666 | J15: =DATEDIF(I15,TODAY(),"Y") -> 20 | K15: Adharcard | L15: 96541238078 | M15: 111 | N15: Sai Nagar | O15: Anantapur | P15: Andhra Pradesh | Q15: KalyanDurgam | R15: Sai Nagar,Anantapur
A16: 13 | B16: C013 | C16: Sai | D16: Sowjanya | E16: =_xlfn.CONCAT(C16,D16) -> SaiSowjanya | F16: =_xlfn.CONCAT(E16,"C013@gmail.com") -> SaiSowjanyaC013@gmail.com | G16: 9712358642 | H16: Female | I16: 38825 | J16: =DATEDIF(I16,TODAY(),"Y") -> 20 | K16: PANCARD | L16: AAAAA1234A | M16: 101 | N16: 2nd Cross | O16: Anantapur | P16: Andhra Pradesh | Q16: Rudrampet | R16: 2nd Cross,Anantapur
A17: 14 | B17: C014 | C17: Gnana | D17: Sree | E17: =_xlfn.CONCAT(C17,D17) -> GnanaSree | F17: =_xlfn.CONCAT(E17,"C014@gmail.com") -> GnanaSreeC014@gmail.com | G17: 9652343124 | H17: Female | I17: 37088 | J17: =DATEDIF(I17,TODAY(),"Y") -> 24 | K17: PANCARD | L17: BBBBB456B | M17: 123 | N17: Jesus Nagar | O17: Anantapur | P17: Andhra Pradesh | Q17: Hyderabad | R17: Jesus Nagar,Anantapur
A18: 15 | B18: C015 | C18: Chandhana | D18: Sree | E18: =_xlfn.CONCAT(C18,D18) -> ChandhanaSree | F18: =_xlfn.CONCAT(E18,"C015@gmail.com") -> ChandhanaSreeC015@gmail.com | G18: 8897662119 | H18: Female | I18: 37511 | J18: =DATEDIF(I18,TODAY(),"Y") -> 23 | K18: Adharcard | L18: 63210458387 | M18: 147 | N18: Naik Nagar | O18: Anantapur | P18: Andhra Pradesh | Q18: Pamidi | R18: Naik Nagar,Anantapur
A19: 16 | B19: C016 | C19: Rahul | D19: Sai | E19: =_xlfn.CONCAT(C19,D19) -> RahulSai | F19: =_xlfn.CONCAT(E19,"C016@gmail.com") -> RahulSaiC016@gmail.com | G19: 6302449968 | H19: Male | I19: 37843 | J19: =DATEDIF(I19,TODAY(),"Y") -> 22 | K19: Adharcard | L19: 96541238078 | M19: 851 | N19: Sai Nagar | O19: Anantapur | P19: Andhra Pradesh | Q19: Gooty | R19: Sai Nagar,Anantapur
A20: 17 | B20: C017 | C20: Virat | D20: Kohili | E20: =_xlfn.CONCAT(C20,D20) -> ViratKohili | F20: =_xlfn.CONCAT(E20,"C017@gmail.com") -> ViratKohiliC017@gmail.com | G20: 8302448877 | H20: Male | I20: 38018 | J20: =DATEDIF(I20,TODAY(),"Y") -> 22 | K20: PANCARD | L20: MKLOI999K | M20: 324 | N20: KalyanDurgam Bypass | O20: Anantapur | P20: Andhra Pradesh | Q20: KalyanDurgam | R20: KalyanDurgam Bypass,Anantapur
A21: 18 | B21: C018 | C21: Prem | D21: Kumar | E21: =_xlfn.CONCAT(C21,D21) -> PremKumar | F21: =_xlfn.CONCAT(E21,"C018@gmail.com") -> PremKumarC018@gmail.com | G21: 6501328746 | H21: Male | I21: 38506 | J21: =DATEDIF(I21,TODAY(),"Y") -> 20 | K21: Adharcard | L21: 63210458387 | M21: 101 | N21: 1st Road | O21: Anantapur | P21: Andhra Pradesh | Q21: ChennaKothapalli | R21: 1st Road,Anantapur
A22: 19 | B22: C019 | C22: Dinesh | D22: Reddy | E22: =_xlfn.CONCAT(C22,D22) -> DineshReddy | F22: =_xlfn.CONCAT(E22,"C019@gmail.com") -> DineshReddyC019@gmail.com | G22: 9985132546 | H22: Male | I22: 38454 | J22: =DATEDIF(I22,TODAY(),"Y") -> 21 | K22: Adharcard | L22: 96541238078 | M22: 107 | N22: Jesus Nagar | O22: Anantapur | P22: Andhra Pradesh | Q22: Dharmavaram | R22: Jesus Nagar,Anantapur
A23: 20 | B23: C020 | C23: Chandhana | D23: Sree | E23: =_xlfn.CONCAT(C23,D23) -> ChandhanaSree | F23: =_xlfn.CONCAT(E23,"C020@gmail.com") -> ChandhanaSreeC020@gmail.com | G23: 9876523344 | H23: Female | I23: 38853 | J23: =DATEDIF(I23,TODAY(),"Y") -> 20 | K23: PANCARD | L23: CCCCC324C | M23: 122 | N23: HousingBoard Colony | O23: Anantapur | P23: Andhra Pradesh | Q23: Pamidi | R23: HousingBoard Colony,Anantapur
A24: 21 | B24: C021 | C24: Priya | D24: Prakash | E24: =_xlfn.CONCAT(C24,D24) -> PriyaPrakash | F24: =_xlfn.CONCAT(E24,"C0201@gmail.com") -> PriyaPrakashC0201@gmail.com | G24: 6301832404 | H24: Female | I24: 37517 | J24: =DATEDIF(I24,TODAY(),"Y") -> 23 | K24: PANCARD | L24: VACGF876B | M24: 501 | N24: Sevenhills Colony | O24: Anantapur | P24: Andhra Pradesh | Q24: Gooty | R24: Sevenhills Colony,Anantapur
A25: 22 | B25: C022 | C25: Nadhini | D25: Royal | E25: =_xlfn.CONCAT(C25,D25) -> NadhiniRoyal | F25: =_xlfn.CONCAT(E25,"C022@gmail.com") -> NadhiniRoyalC022@gmail.com | G25: 9502991554 | H25: Female | I25: 37622 | J25: =DATEDIF(I25,TODAY(),"Y") -> 23 | K25: Adharcard | L25: 63210458387 | M25: 111 | N25: Sai Nagar | O25: Anantapur | P25: Andhra Pradesh | Q25: KalyanDurgam | R25: Sai Nagar,Anantapur
A26: 23 | B26: C023 | C26: Naveen | D26: Kumar | E26: =_xlfn.CONCAT(C26,D26) -> NaveenKumar | F26: =_xlfn.CONCAT(E26,"C023@gmail.com") -> NaveenKumarC023@gmail.com | G26: 9712358642 | H26: Male | I26: 38234 | J26: =DATEDIF(I26,TODAY(),"Y") -> 21 | K26: Adharcard | L26: 96541238078 | M26: 101 | N26: 2nd Cross | O26: Anantapur | P26: Andhra Pradesh | Q26: Rudrampet | R26: 2nd Cross,Anantapur
A27: 24 | B27: C024 | C27: Hema | D27: Latha | E27: =_xlfn.CONCAT(C27,D27) -> Hema Latha | F27: =_xlfn.CONCAT(E27,"C024@gmail.com") -> Hema LathaC024@gmail.com | G27: 9652343124 | H27: Female | I27: 38388 | J27: =DATEDIF(I27,TODAY(),"Y") -> 21 | K27: PANCARD | L27: MKLOI999K | M27: 123 | N27: Jesus Nagar | O27: Anantapur | P27: Andhra Pradesh | Q27: Hyderabad | R27: Jesus Nagar,Anantapur
A28: 25 | B28: C025 | C28: Hari | D28: Priya | E28: =_xlfn.CONCAT(C28,D28) -> Hari Priya | F28: =_xlfn.CONCAT(E28,"C025@gmail.com") -> Hari PriyaC025@gmail.com | G28: 8897662119 | H28: Female | I28: 37570 | J28: =DATEDIF(I28,TODAY(),"Y") -> 23 | K28: Adharcard | L28: 98745612309 | M28: 147 | N28: Naik Nagar | O28: Anantapur | P28: Andhra Pradesh | Q28: Pamidi | R28: Naik Nagar,Anantapur
A29: 26 | B29: C026 | C29: Jaya | D29: Lashmi | E29: =_xlfn.CONCAT(C29,D29) -> JayaLashmi | F29: =_xlfn.CONCAT(E29,"C026@gmail.com") -> JayaLashmiC026@gmail.com | G29: 6302449968 | H29: Female | I29: 38095 | J29: =DATEDIF(I29,TODAY(),"Y") -> 22 | K29: Adharcard | L29: 96541238078 | M29: 851 | N29: Sai Nagar | O29: Anantapur | P29: Andhra Pradesh | Q29: Gooty | R29: Sai Nagar,Anantapur
A30: 27 | B30: C027 | C30: Lakshmi | D30: Priya | E30: =_xlfn.CONCAT(C30,D30) -> LakshmiPriya | F30: =_xlfn.CONCAT(E30,"C027@gmail.com") -> LakshmiPriyaC027@gmail.com | G30: 8302448877 | H30: Female | I30: 38549 | J30: =DATEDIF(I30,TODAY(),"Y") -> 20 | K30: PANCARD | L30: CCCCC324C | M30: 324 | N30: KalyanDurgam Bypass | O30: Anantapur | P30: Andhra Pradesh | Q30: KalyanDurgam | R30: KalyanDurgam Bypass,Anantapur
A31: 28 | B31: C028 | C31: Lakshmi | D31: Devi | E31: =_xlfn.CONCAT(C31,D31) -> LakshmiDevi | F31: =_xlfn.CONCAT(E31,"C028@gmail.com") -> LakshmiDeviC028@gmail.com | G31: 6501328746 | H31: Female | I31: 38971 | J31: =DATEDIF(I31,TODAY(),"Y") -> 19 | K31: PANCARD | L31: VACGF876B | M31: 101 | N31: 1st Road | O31: Anantapur | P31: Andhra Pradesh | Q31: ChennaKothapalli | R31: 1st Road,Anantapur
A32: 29 | B32: C029 | C32: Jaya | D32: Surya | E32: =_xlfn.CONCAT(C32,D32) -> JayaSurya | F32: =_xlfn.CONCAT(E32,"C029@gmail.com") -> JayaSuryaC029@gmail.com | G32: 9985132546 | H32: Male | I32: 37699 | J32: =DATEDIF(I32,TODAY(),"Y") -> 23 | K32: Adharcard | L32: 63210458387 | M32: 107 | N32: Jesus Nagar | O32: Anantapur | P32: Andhra Pradesh | Q32: Dharmavaram | R32: Jesus Nagar,Anantapur
A33: 30 | B33: C030 | C33: Simha | D33: Priya | E33: =_xlfn.CONCAT(C33,D33) -> SimhaPriya | F33: =_xlfn.CONCAT(E33,"C030@gmail.com") -> SimhaPriyaC030@gmail.com | G33: 9876523344 | H33: Female | I33: 38916 | J33: =DATEDIF(I33,TODAY(),"Y") -> 19 | K33: Adharcard | L33: 96541238078 | M33: 122 | N33: HousingBoard Colony | O33: Anantapur | P33: Andhra Pradesh | Q33: Pamidi | R33: HousingBoard Colony,Anantapur
A34: 31 | B34: C031 | C34: Eshwar | D34: Reddy | E34: =_xlfn.CONCAT(C34,D34) -> EshwarReddy | F34: =_xlfn.CONCAT(E34,"C031@gmail.com") -> EshwarReddyC031@gmail.com | G34: 6301832404 | H34: Male | I34: 37936 | J34: =DATEDIF(I34,TODAY(),"Y") -> 22 | K34: PANCARD | M34: 501 | N34: Sevenhills Colony | O34: Anantapur | P34: Andhra Pradesh | Q34: Gooty | R34: Sevenhills Colony,Anantapur
A35: 32 | B35: C032 | C35: Rahul | D35: Sai | E35: =_xlfn.CONCAT(C35,D35) -> RahulSai | F35: =_xlfn.CONCAT(E35,"C032@gmail.com") -> RahulSaiC032@gmail.com | G35: 9502991554 | H35: Male | I35: 38576 | J35: =DATEDIF(I35,TODAY(),"Y") -> 20 | K35: Adharcard | L35: 63210458387 | M35: 111 | N35: Sai Nagar | O35: Anantapur | P35: Andhra Pradesh | Q35: KalyanDurgam | R35: Sai Nagar,Anantapur
A36: 33 | B36: C033 | C36: Chaitanya | D36: Lakshmi | E36: =_xlfn.CONCAT(C36,D36) -> ChaitanyaLakshmi | F36: =_xlfn.CONCAT(E36,"C033@gmail.com") -> ChaitanyaLakshmiC033@gmail.com | G36: 9712358642 | H36: Female | I36: 37517 | J36: =DATEDIF(I36,TODAY(),"Y") -> 23 | K36: Adharcard | L36: 96541238078 | M36: 101 | N36: 2nd Cross | O36: Anantapur | P36: Andhra Pradesh | Q36: Rudrampet | R36: 2nd Cross,Anantapur
A37: 34 | B37: C034 | C37: Sohan | D37: Sai | E37: =_xlfn.CONCAT(C37,D37) -> SohanSai | F37: =_xlfn.CONCAT(E37,"C034@gmail.com") -> SohanSaiC034@gmail.com | G37: 9652343124 | H37: Male | I37: 38089 | J37: =DATEDIF(I37,TODAY(),"Y") -> 22 | K37: PANCARD | L37: AAAAA1234A | M37: 123 | N37: Jesus Nagar | O37: Anantapur | P37: Andhra Pradesh | Q37: Hyderabad | R37: Jesus Nagar,Anantapur
A38: 35 | B38: C035 | C38: Madhavi | D38: Latha | E38: =_xlfn.CONCAT(C38,D38) -> MadhaviLatha | F38: =_xlfn.CONCAT(E38,"C035@gmail.com") -> MadhaviLathaC035@gmail.com | G38: 8897662119 | H38: Female | I38: 37757 | J38: =DATEDIF(I38,TODAY(),"Y") -> 23 | K38: PANCARD | L38: BBBBB456B | M38: 147 | N38: Naik Nagar | O38: Anantapur | P38: Andhra Pradesh | Q38: Pamidi | R38: Naik Nagar,Anantapur
A39: 36 | B39: C036 | C39: Maha | D39: Lakshmi | E39: =_xlfn.CONCAT(C39,D39) -> MahaLakshmi | F39: =_xlfn.CONCAT(E39,"C036@gmail.com") -> MahaLakshmiC036@gmail.com | G39: 6302449968 | H39: Female | I39: 38248 | J39: =DATEDIF(I39,TODAY(),"Y") -> 21 | K39: Adharcard | L39: 63210458387 | M39: 851 | N39: Sai Nagar | O39: Anantapur | P39: Andhra Pradesh | Q39: Gooty | R39: Sai Nagar,Anantapur
A40: 37 | B40: C037 | C40: Lakshmi | D40: Sree | E40: =_xlfn.CONCAT(C40,D40) -> LakshmiSree | F40: =_xlfn.CONCAT(E40,"C037@gmail.com") -> LakshmiSreeC037@gmail.com | G40: 8302448877 | H40: Female | I40: 38353 | J40: =DATEDIF(I40,TODAY(),"Y") -> 21 | K40: Adharcard | L40: 96541238078 | M40: 324 | N40: KalyanDurgam Bypass | O40: Anantapur | P40: Andhra Pradesh | Q40: KalyanDurgam | R40: KalyanDurgam Bypass,Anantapur
A41: 38 | B41: C038 | C41: Sree | D41: nivas | E41: =_xlfn.CONCAT(C41,D41) -> Sreenivas | F41: =_xlfn.CONCAT(E41,"C038@gmail.com") -> SreenivasC038@gmail.com | G41: 6501328746 | H41: Male | I41: 38964 | J41: =DATEDIF(I41,TODAY(),"Y") -> 19 | K41: PANCARD | L41: MNJKL879L | M41: 101 | N41: 1st Road | O41: Anantapur | P41: Andhra Pradesh | Q41: ChennaKothapalli | R41: 1st Road,Anantapur
...

Sheet Room Details
A2: Coustmer Room Details
A3: S.no | B3: Booking ID | C3: Room Number | D3: Room Type | E3: Floor | F3: Bed Type | G3: Price per day | H3: Check-in-Date | I3: Check-out-date | J3: No.of Days | K3: Max occupancy | L3: AC/Non AC | M3: Status
A4: 1 | B4: B001 | C4: R102 | D4: Single | E4: 1 | F4: Single Bed | G4: {=_xlfn.SWITCH(F4,"Single Bed","2000","Double Bed","4000","Queen Bed","5000","King Bed","6000")} -> 2000 | H4: 45728 | I4: 45730 | J4: =I4-H4 -> 2 | K4: 1 | L4: AC | M4: =IF(TODAY()>I4,"Available","Booked") -> Available
A5: 2 | B5: B002 | C5: R103 | D5: Double | E5: 3 | F5: Double Bed | G5: {=_xlfn.SWITCH(F5,"Single Bed","2000","Double Bed","4000","Queen Bed","5000","King Bed","6000")} -> 4000 | H5: 45699 | I5: 45699 | J5: =I5-H5 -> 0 | K5: 2 | L5: Non-AC | M5: =IF(TODAY()>I5,"Available","Booked") -> Available
A6: 3 | B6: B003 | C6: R104 | D6: Deluxe | E6: 2 | F6: Queen Bed | G6: {=_xlfn.SWITCH(F6,"Single Bed","2000","Double Bed","4000","Queen Bed","5000","King Bed","6000")} -> 5000 | H6: 45882 | I6: 45883 | J6: =I6-H6 -> 1 | K6: 3 | L6: AC | M6: =IF(TODAY()>I6,"Available","Booked") -> Available
A7: 4 | B7: B004 | C7: R105 | D7: Suite | E7: 1 | F7: King Bed | G7: {=_xlfn.SWITCH(F7,"Single Bed","2000","Double Bed","4000","Queen Bed","5000","King Bed","6000")} -> 6000 | H7: 45727 | I7: 45729 | J7: =I7-H7 -> 2 | K7: 2 | L7: AC | M7: =IF(TODAY()>I7,"Available","Booked") -> Available
A8: 5 | B8: B005 | C8: R106 | D8: Single | E8: 4 | F8: Single Bed | G8: {=_xlfn.SWITCH(F8,"Single Bed","2000","Double Bed","4000","Queen Bed","5000","King Bed","6000")} -> 2000 | H8: 46003 | I8: 46005 | J8: =I8-H8 -> 2 | K8: 1 | L8: AC | M8: =IF(TODAY()>I8,"Available","Booked") -> Available
A9: 6 | B9: B006 | C9: R107 | D9: Double | E9: 2 | F9: Single Bed | G9: {=_xlfn.SWITCH(F9,"Single Bed","2000","Double Bed","4000","Queen Bed","5000","King Bed","6000")} -> 2000 | H9: 45748 | I9: 45748 | J9: =I9-H9 -> 0 | K9: 1 | L9: Non-AC | M9: =IF(TODAY()>I9,"Available","Booked") -> Available
A10: 7 | B10: B007 | C10: R108 | D10: Deluxe | E10: 2 | F10: Double Bed | G10: {=_xlfn.SWITCH(F10,"Single Bed","2000","Double Bed","4000","Queen Bed","5000","King Bed","6000")} -> 4000 | H10: 45788 | I10: 45789 | J10: =I10-H10 -> 1 | K10: 2 | L10: Non-AC | M10: =IF(TODAY()>I10,"Available","Booked") -> Available
A11: 8 | B11: B008 | C11: R109 | D11: Suite | E11: 1 | F11: Double Bed | G11: {=_xlfn.SWITCH(F11,"Single Bed","2000","Double Bed","4000","Queen Bed","5000","King Bed","6000")} -> 4000 | H11: 45911 | I11: 45911 | J11: =I11-H11 -> 0 | K11: 2 | L11: AC | M11: =IF(TODAY()>I11,"Available","Booked") -> Available
A12: 9 | B12: B009 | C12: R110 | D12: Single | E12: 3 | F12: Single Bed | G12: {=_xlfn.SWITCH(F12,"Single Bed","2000","Double Bed","4000","Queen Bed","5000","King Bed","6000")} -> 2000 | H12: 45873 | I12: 45874 | J12: =I12-H12 -> 1 | K12: 1 | L12: AC | M12: =IF(TODAY()>I12,"Available","Booked") -> Available
A13: 10 | B13: B010 | C13: R111 | D13: Double | E13: 2 | F13: Double Bed | G13: {=_xlfn.SWITCH(F13,"Single Bed","2000","Double Bed","4000","Queen Bed","5000","King Bed","6000")} -> 4000 | H13: 45816 | I13: 45817 | J13: =I13-H13 -> 1 | K13: 2 | L13: AC | M13: =IF(TODAY()>I13,"Available","Booked") -> Available
A14: 11 | B14: B011 | C14: R112 | D14: Deluxe | E14: 1 | F14: Queen Bed | G14: {=_xlfn.SWITCH(F14,"Single Bed","2000","Double Bed","4000","Queen Bed","5000","King Bed","6000")} -> 5000 | H14: 45728 | I14: 45730 | J14: =I14-H14 -> 2 | K14: 3 | L14: Non-AC | M14: =IF(TODAY()>I14,"Available","Booked") -> Available
A15: 12 | B15: B012 | C15: R113 | D15: Suite | E15: 4 | F15: King Bed | G15: {=_xlfn.SWITCH(F15,"Single Bed","2000","Double Bed","4000","Queen Bed","5000","King Bed","6000")} -> 6000 | H15: 45699 | I15: 45699 | J15: =I15-H15 -> 0 | K15: 3 | L15: Non-AC | M15: =IF(TODAY()>I15,"Available","Booked") -> Available
... A53: 50 | B53: B050 | C53: R151 | D53: Single | E53: 2 | F53: Queen Bed | G53: {=_xlfn.SWITCH(F53,"Single Bed","2000","Double Bed","4000","Queen Bed","5000","King Bed","6000")} -> 5000 | H53: 45816 | I53: 45817 | J53: =I53-H53 -> 1 | K53: 3 | L53: AC | M53: =IF(TODAY()>I53,"Available","Booked") -> Available

Sheet Dash Board-1
Q2: Room Type | R2: Floor | S2: Bed Type | T2: Price per day | U2: Check-in-Date | V2: Check-out-date | W2: No.of Days | X2: Max occupancy | Y2: AC/Non AC
A3: Row Labels | B3: Sum of No.of Days | Q3: Single | R3: 1 | S3: Single Bed | T3: {=_xlfn.SWITCH(S3,"Single Bed","2000","Double Bed","4000","Queen Bed","5000","King Bed","6000")} -> 2000 | U3: 45728 | V3: 45730 | W3: =V3-U3 -> 2 | X3: 1 | Y3: AC
A4: Deluxe | B4: 15 | Q4: Double | R4: 3 | S4: Double Bed | T4: {=_xlfn.SWITCH(S4,"Single Bed","2000","Double Bed","4000","Queen Bed","5000","King Bed","6000")} -> 4000 | U4: 45699 | V4: 45699 | W4: =V4-U4 -> 0 | X4: 2 | Y4: Non-AC
A5: Double Bed | B5: 7 | Q5: Deluxe | R5: 2 | S5: Queen Bed | T5: {=_xlfn.SWITCH(S5,"Single Bed","2000","Double Bed","4000","Queen Bed","5000","King Bed","6000")} -> 5000 | U5: 45882 | V5: 45883 | W5: =V5-U5 -> 1 | X5: 3 | Y5: AC
A6: 4000 | B6: 7 | Q6: Suite | R6: 1 | S6: King Bed | T6: {=_xlfn.SWITCH(S6,"Single Bed","2000","Double Bed","4000","Queen Bed","5000","King Bed","6000")} -> 6000 | U6: 45727 | V6: 45729 | W6: =V6-U6 -> 2 | X6: 2 | Y6: AC
A7: Mar | B7: 2 | Q7: Single | R7: 4 | S7: Single Bed | T7: {=_xlfn.SWITCH(S7,"Single Bed","2000","Double Bed","4000","Queen Bed","5000","King Bed","6000")} -> 2000 | U7: 46003 | V7: 46005 | W7: =V7-U7 -> 2 | X7: 1 | Y7: AC
A8: May | B8: 1 | Q8: Double | R8: 2 | S8: Single Bed | T8: {=_xlfn.SWITCH(S8,"Single Bed","2000","Double Bed","4000","Queen Bed","5000","King Bed","6000")} -> 2000 | U8: 45748 | V8: 45748 | W8: =V8-U8 -> 0 | X8: 1 | Y8: Non-AC
A9: Aug | B9: 2 | Q9: Deluxe | R9: 2 | S9: Double Bed | T9: {=_xlfn.SWITCH(S9,"Single Bed","2000","Double Bed","4000","Queen Bed","5000","King Bed","6000")} -> 4000 | U9: 45788 | V9: 45789 | W9: =V9-U9 -> 1 | X9: 2 | Y9: Non-AC
A10: Sep | B10: 0 | Q10: Suite | R10: 1 | S10: Double Bed | T10: {=_xlfn.SWITCH(S10,"Single Bed","2000","Double Bed","4000","Queen Bed","5000","King Bed","6000")} -> 4000 | U10: 45911 | V10: 45911 | W10: =V10-U10 -> 0 | X10: 2 | Y10: AC
A11: Dec | B11: 2 | Q11: Single | R11: 3 | S11: Single Bed | T11: {=_xlfn.SWITCH(S11,"Single Bed","2000","Double Bed","4000","Queen Bed","5000","King Bed","6000")} -> 2000 | U11: 45873 | V11: 45874 | W11: =V11-U11 -> 1 | X11: 1 | Y11: AC
A12: Queen Bed | B12: 8 | Q12: Double | R12: 2 | S12: Double Bed | T12: {=_xlfn.SWITCH(S12,"Single Bed","2000","Double Bed","4000","Queen Bed","5000","King Bed","6000")} -> 4000 | U12: 45816 | V12: 45817 | W12: =V12-U12 -> 1 | X12: 2 | Y12: AC
A13: 5000 | B13: 8 | Q13: Deluxe | R13: 1 | S13: Queen Bed | T13: {=_xlfn.SWITCH(S13,"Single Bed","2000","Double Bed","4000","Queen Bed","5000","King Bed","6000")} -> 5000 | U13: 45728 | V13: 45730 | W13: =V13-U13 -> 2 | X13: 3 | Y13: Non-AC
A14: Mar | B14: 2 | Q14: Suite | R14: 4 | S14: King Bed | T14: {=_xlfn.SWITCH(S14,"Single Bed","2000","Double Bed","4000","Queen Bed","5000","King Bed","6000")} -> 6000 | U14: 45699 | V14: 45699 | W14: =V14-U14 -> 0 | X14: 3 | Y14: Non-AC
A15: May | B15: 1 | Q15: Single | R15: 2 | S15: Single Bed | T15: {=_xlfn.SWITCH(S15,"Single Bed","2000","Double Bed","4000","Queen Bed","5000","King Bed","6000")} -> 2000 | U15: 45882 | V15: 45883 | W15: =V15-U15 -> 1 | X15: 1 | Y15: AC
... A52: Sep | B52: 0 | Q52: Single | R52: 2 | S52: Queen Bed | T52: {=_xlfn.SWITCH(S52,"Single Bed","2000","Double Bed","4000","Queen Bed","5000","King Bed","6000")} -> 5000 | U52: 45816 | V52: 45817 | W52: =V52-U52 -> 1 | X52: 3 | Y52: AC
A53: King Bed | B53: 6
A54: 6000 | B54: 6
A55: Feb | B55: 0
A56: Mar | B56: 4
A57: Apr | B57: 0
A58: Jun | B58: 1
A59: Aug | B59: 1
A60: Sep | B60: 0
A61: Grand Total | B61: 50

Sheet Room Lookup
A1: Booking ID | B1: Room Number | C1: Room Type | D1: Floor | E1: Bed Type | F1: Price per day
A2: B001 | B2: R102 | C2: Single | D2: 1 | E2: Single Bed | F2: {=_xlfn.SWITCH(E2,"Single Bed","2000","Double Bed","4000","Queen Bed","5000","King Bed","6000")} -> 2000
A3: B002 | B3: R103 | C3: Double | D3: 3 | E3: Double Bed | F3: {=_xlfn.SWITCH(E3,"Single Bed","2000","Double Bed","4000","Queen Bed","5000","King Bed","6000")} -> 4000
A4: B003 | B4: R104 | C4: Deluxe | D4: 2 | E4: Queen Bed | F4: {=_xlfn.SWITCH(E4,"Single Bed","2000","Double Bed","4000","Queen Bed","5000","King Bed","6000")} -> 5000
A5: B004 | B5: R105 | C5: Suite | D5: 1 | E5: King Bed | F5: {=_xlfn.SWITCH(E5,"Single Bed","2000","Double Bed","4000","Queen Bed","5000","King Bed","6000")} -> 6000
A6: B005 | B6: R106 | C6: Single | D6: 4 | E6: Single Bed | F6: {=_xlfn.SWITCH(E6,"Single Bed","2000","Double Bed","4000","Queen Bed","5000","King Bed","6000")} -> 2000 | J6: Room Details
A7: B006 | B7: R107 | C7: Double | D7: 2 | E7: Single Bed | F7: {=_xlfn.SWITCH(E7,"Single Bed","2000","Double Bed","4000","Queen Bed","5000","King Bed","6000")} -> 2000 | J7: Book Id | K7: Room Number | L7: Floor | M7: Price
A8: B007 | B8: R108 | C8: Deluxe | D8: 2 | E8: Double Bed | F8: {=_xlfn.SWITCH(E8,"Single Bed","2000","Double Bed","4000","Queen Bed","5000","King Bed","6000")} -> 4000 | J8: B003 | K8: {=VLOOKUP(J8,A1:F51,{2,4,6},0)} -> R104 | L8: 2 | M8: 5000
A9: B008 | B9: R109 | C9: Suite | D9: 1 | E9: Double Bed | F9: {=_xlfn.SWITCH(E9,"Single Bed","2000","Double Bed","4000","Queen Bed","5000","King Bed","6000")} -> 4000 | J9: B004 | K9: {=VLOOKUP(J9,A1:F51,{2,4,6},0)} -> R105 | L9: 1 | M9: 6000
A10: B009 | B10: R110 | C10: Single | D10: 3 | E10: Single Bed | F10: {=_xlfn.SWITCH(E10,"Single Bed","2000","Double Bed","4000","Queen Bed","5000","King Bed","6000")} -> 2000
A11: B010 | B11: R111 | C11: Double | D11: 2 | E11: Double Bed | F11: {=_xlfn.SWITCH(E11,"Single Bed","2000","Double Bed","4000","Queen Bed","5000","King Bed","6000")} -> 4000
A12: B011 | B12: R112 | C12: Deluxe | D12: 1 | E12: Queen Bed | F12: {=_xlfn.SWITCH(E12,"Single Bed","2000","Double Bed","4000","Queen Bed","5000","King Bed","6000")} -> 5000
A13: B012 | B13: R113 | C13: Suite | D13: 4 | E13: King Bed | F13: {=_xlfn.SWITCH(E13,"Single Bed","2000","Double Bed","4000","Queen Bed","5000","King Bed","6000")} -> 6000 | N13: Room Details
A14: B013 | B14: R114 | C14: Single | D14: 2 | E14: Single Bed | F14: {=_xlfn.SWITCH(E14,"Single Bed","2000","Double Bed","4000","Queen Bed","5000","King Bed","6000")} -> 2000 | N14: Book ID | O14: Room Number | P14: Room Type | Q14: Floor | R14: Bed Type | S14: Price per day
A15: B014 | B15: R115 | C15: Double | D15: 2 | E15: Single Bed | F15: {=_xlfn.SWITCH(E15,"Single Bed","2000","Double Bed","4000","Queen Bed","5000","King Bed","6000")} -> 2000 | N15: B007 | O15: {=_xlfn.XLOOKUP(N15,A1:A51,B1:F51)} -> R108 | P15: Deluxe | Q15: 2 | R15: Double Bed | S15: 4000
A16: B015 | B16: R116 | C16: Deluxe | D16: 1 | E16: Double Bed | F16: {=_xlfn.SWITCH(E16,"Single Bed","2000","Double Bed","4000","Queen Bed","5000","King Bed","6000")} -> 4000 | N16: B009 | O16: {=_xlfn.XLOOKUP(N16,A1:A51,B1:F51)} -> R110 | P16: Single | Q16: 3 | R16: Single Bed | S16: 2000
A17: B016 | B17: R117 | C17: Suite | D17: 3 | E17: Double Bed | F17: {=_xlfn.SWITCH(E17,"Single Bed","2000","Double Bed","4000","Queen Bed","5000","King Bed","6000")} -> 4000
A18: B017 | B18: R118 | C18: Single | D18: 2 | E18: Single Bed | F18: {=_xlfn.SWITCH(E18,"Single Bed","2000","Double Bed","4000","Queen Bed","5000","King Bed","6000")} -> 2000
A19: B018 | B19: R119 | C19: Double | D19: 1 | E19: Double Bed | F19: {=_xlfn.SWITCH(E19,"Single Bed","2000","Double Bed","4000","Queen Bed","5000","King Bed","6000")} -> 4000
A20: B019 | B20: R120 | C20: Deluxe | D20: 4 | E20: Queen Bed | F20: {=_xlfn.SWITCH(E20,"Single Bed","2000","Double Bed","4000","Queen Bed","5000","King Bed","6000")} -> 5000
A21: B020 | B21: R121 | C21: Suite | D21: 2 | E21: King Bed | F21: {=_xlfn.SWITCH(E21,"Single Bed","2000","Double Bed","4000","Queen Bed","5000","King Bed","6000")} -> 6000
A22: B021 | B22: R122 | C22: Single | D22: 2 | E22: Single Bed | F22: {=_xlfn.SWITCH(E22,"Single Bed","2000","Double Bed","4000","Queen Bed","5000","King Bed","6000")} -> 2000
A23: B022 | B23: R123 | C23: Double | D23: 1 | E23: Single Bed | F23: {=_xlfn.SWITCH(E23,"Single Bed","2000","Double Bed","4000","Queen Bed","5000","King Bed","6000")} -> 2000
A24: B023 | B24: R124 | C24: Deluxe | D24: 3 | E24: Double Bed | F24: {=_xlfn.SWITCH(E24,"Single Bed","2000","Double Bed","4000","Queen Bed","5000","King Bed","6000")} -> 4000
A25: B024 | B25: R125 | C25: Suite | D25: 2 | E25: Double Bed | F25: {=_xlfn.SWITCH(E25,"Single Bed","2000","Double Bed","4000","Queen Bed","5000","King Bed","6000")} -> 4000
A26: B025 | B26: R126 | C26: Single | D26: 1 | E26: Single Bed | F26: {=_xlfn.SWITCH(E26,"Single Bed","2000","Double Bed","4000","Queen Bed","5000","King Bed","6000")} -> 2000
A27: B026 | B27: R127 | C27: Double | D27: 4 | E27: Double Bed | F27: {=_xlfn.SWITCH(E27,"Single Bed","2000","Double Bed","4000","Queen Bed","5000","King Bed","6000")} -> 4000
A28: B027 | B28: R128 | C28: Deluxe | D28: 2 | E28: Queen Bed | F28: {=_xlfn.SWITCH(E28,"Single Bed","2000","Double Bed","4000","Queen Bed","5000","King Bed","6000")} -> 5000
... A51: B050 | B51: R151 | C51: Single | D51: 2 | E51: Queen Bed | F51: {=_xlfn.SWITCH(E51,"Single Bed","2000","Double Bed","4000","Queen Bed","5000","King Bed","6000")} -> 5000

Sheet Food Details
B2: Coustmer Food Details
A3: S.no | B3: Order Id | C3: Booking ID | D3: Room No | E3: Food ID | F3: Food Type | G3: Food Name | H3: Order Date | I3: Quantity | J3: Price | K3: Total Amount
A4: 1 | B4: O11 | C4: ='Room Details'!B4 -> B001 | D4: ='Room Details'!C4 -> R102 | E4: F01 | F4: Non-Veg | G4: {=_xlfn.SWITCH(E4,"F01","Biryani","F02","Puri","F03","Mutton Biryani","F04","Mutton Soup","F05","Veg Biryani","F06","Panner Biryani","F07","Mushroom Biryani")} -> Biryani | H4: 45728 | I4: 1 | J4: {=_xlfn.SWITCH(E4,"F01","500","F02","100","F03","700","F04","300","F05","500","F06","350","F07","400")} -> 500 | K4: =I4*J4 -> 500
A5: 2 | B5: O12 | C5: ='Room Details'!B5 -> B002 | D5: ='Room Details'!C5 -> R103 | E5: F02 | F5: Veg | G5: {=_xlfn.SWITCH(E5,"F01","Biryani","F02","Puri","F03","Mutton Biryani","F04","Mutton Soup","F05","Veg Biryani","F06","Panner Biryani","F07","Mushroom Biryani")} -> Puri | H5: 45699 | I5: 2 | J5: {=_xlfn.SWITCH(E5,"F01","500","F02","100","F03","700","F04","300","F05","500","F06","350","F07","400")} -> 100 | K5: =I5*J5 -> 200
A6: 3 | B6: O13 | C6: ='Room Details'!B6 -> B003 | D6: ='Room Details'!C6 -> R104 | E6: F03 | F6: Non-Veg | G6: {=_xlfn.SWITCH(E6,"F01","Biryani","F02","Puri","F03","Mutton Biryani","F04","Mutton Soup","F05","Veg Biryani","F06","Panner Biryani","F07","Mushroom Biryani")} -> Mutton Biryani | H6: 45882 | I6: 2 | J6: {=_xlfn.SWITCH(E6,"F01","500","F02","100","F03","700","F04","300","F05","500","F06","350","F07","400")} -> 700 | K6: =I6*J6 -> 1400
A7: 4 | B7: O14 | C7: ='Room Details'!B7 -> B004 | D7: ='Room Details'!C7 -> R105 | E7: F04 | F7: Non-Veg | G7: {=_xlfn.SWITCH(E7,"F01","Biryani","F02","Puri","F03","Mutton Biryani","F04","Mutton Soup","F05","Veg Biryani","F06","Panner Biryani","F07","Mushroom Biryani")} -> Mutton Soup | H7: 45727 | I7: 3 | J7: {=_xlfn.SWITCH(E7,"F01","500","F02","100","F03","700","F04","300","F05","500","F06","350","F07","400")} -> 300 | K7: =I7*J7 -> 900
A8: 5 | B8: O15 | C8: ='Room Details'!B8 -> B005 | D8: ='Room Details'!C8 -> R106 | E8: F05 | F8: Veg | G8: {=_xlfn.SWITCH(E8,"F01","Biryani","F02","Puri","F03","Mutton Biryani","F04","Mutton Soup","F05","Veg Biryani","F06","Panner Biryani","F07","Mushroom Biryani")} -> Veg Biryani | H8: 46003 | I8: 1 | J8: {=_xlfn.SWITCH(E8,"F01","500","F02","100","F03","700","F04","300","F05","500","F06","350","F07","400")} -> 500 | K8: =I8*J8 -> 500
A9: 6 | B9: O16 | C9: ='Room Details'!B9 -> B006 | D9: ='Room Details'!C9 -> R107 | E9: F06 | F9: Veg | G9: {=_xlfn.SWITCH(E9,"F01","Biryani","F02","Puri","F03","Mutton Biryani","F04","Mutton Soup","F05","Veg Biryani","F06","Panner Biryani","F07","Mushroom Biryani")} -> Panner Biryani | H9: 45748 | I9: 2 | J9: {=_xlfn.SWITCH(E9,"F01","500","F02","100","F03","700","F04","300","F05","500","F06","350","F07","400")} -> 350 | K9: =I9*J9 -> 700
A10: 7 | B10: O17 | C10: ='Room Details'!B10 -> B007 | D10: ='Room Details'!C10 -> R108 | E10: F07 | F10: Veg | G10: {=_xlfn.SWITCH(E10,"F01","Biryani","F02","Puri","F03","Mutton Biryani","F04","Mutton Soup","F05","Veg Biryani","F06","Panner Biryani","F07","Mushroom Biryani")} -> Mushroom Biryani | H10: 45788 | I10: 2 | J10: {=_xlfn.SWITCH(E10,"F01","500","F02","100","F03","700","F04","300","F05","500","F06","350","F07","400")} -> 400 | K10: =I10*J10 -> 800
A11: 8 | B11: O18 | C11: ='Room Details'!B11 -> B008 | D11: ='Room Details'!C11 -> R109 | E11: F03 | F11: Non-Veg | G11: {=_xlfn.SWITCH(E11,"F01","Biryani","F02","Puri","F03","Mutton Biryani","F04","Mutton Soup","F05","Veg Biryani","F06","Panner Biryani","F07","Mushroom Biryani")} -> Mutton Biryani | H11: 45911 | I11: 4 | J11: {=_xlfn.SWITCH(E11,"F01","500","F02","100","F03","700","F04","300","F05","500","F06","350","F07","400")} -> 700 | K11: =I11*J11 -> 2800
A12: 9 | B12: O19 | C12: ='Room Details'!B12 -> B009 | D12: ='Room Details'!C12 -> R110 | E12: F04 | F12: Non-Veg | G12: {=_xlfn.SWITCH(E12,"F01","Biryani","F02","Puri","F03","Mutton Biryani","F04","Mutton Soup","F05","Veg Biryani","F06","Panner Biryani","F07","Mushroom Biryani")} -> Mutton Soup | H12: 45873 | I12: 2 | J12: {=_xlfn.SWITCH(E12,"F01","500","F02","100","F03","700","F04","300","F05","500","F06","350","F07","400")} -> 300 | K12: =I12*J12 -> 600
A13: 10 | B13: O20 | C13: ='Room Details'!B13 -> B010 | D13: ='Room Details'!C13 -> R111 | E13: F05 | F13: Veg | G13: {=_xlfn.SWITCH(E13,"F01","Biryani","F02","Puri","F03","Mutton Biryani","F04","Mutton Soup","F05","Veg Biryani","F06","Panner Biryani","F07","Mushroom Biryani")} -> Veg Biryani | H13: 45816 | I13: 1 | J13: {=_xlfn.SWITCH(E13,"F01","500","F02","100","F03","700","F04","300","F05","500","F06","350","F07","400")} -> 500 | K13: =I13*J13 -> 500
A14: 11 | B14: O21 | C14: ='Room Details'!B14 -> B011 | D14: ='Room Details'!C14 -> R112 | E14: F06 | F14: Veg | G14: {=_xlfn.SWITCH(E14,"F01","Biryani","F02","Puri","F03","Mutton Biryani","F04","Mutton Soup","F05","Veg Biryani","F06","Panner Biryani","F07","Mushroom Biryani")} -> Panner Biryani | H14: 45728 | I14: 2 | J14: {=_xlfn.SWITCH(E14,"F01","500","F02","100","F03","700","F04","300","F05","500","F06","350","F07","400")} -> 350 | K14: =I14*J14 -> 700
A15: 12 | B15: O22 | C15: ='Room Details'!B15 -> B012 | D15: ='Room Details'!C15 -> R113 | E15: F07 | F15: Veg | G15: {=_xlfn.SWITCH(E15,"F01","Biryani","F02","Puri","F03","Mutton Biryani","F04","Mutton Soup","F05","Veg Biryani","F06","Panner Biryani","F07","Mushroom Biryani")} -> Mushroom Biryani | H15: 45699 | I15: 1 | J15: {=_xlfn.SWITCH(E15,"F01","500","F02","100","F03","700","F04","300","F05","500","F06","350","F07","400")} -> 400 | K15: =I15*J15 -> 400
... A53: 50 | B53: O60 | C53: ='Room Details'!B53 -> B050 | D53: ='Room Details'!C53 -> R151 | E53: F01 | F53: Non-Veg | G53: {=_xlfn.SWITCH(E53,"F01","Biryani","F02","Puri","F03","Mutton Biryani","F04","Mutton Soup","F05","Veg Biryani","F06","Panner Biryani","F07","Mushroom Biryani")} -> Biryani | H53: 45816 | I53: 2 | J53: {=_xlfn.SWITCH(E53,"F01","500","F02","100","F03","700","F04","300","F05","500","F06","350","F07","400")} -> 500 | K53: =I53*J53 -> 1000

Sheet Dash Board-2
W2: Food ID | X2: Food Type | Y2: Food Name | Z2: Order Type | AA2: Quantity | AB2: Price | AC2: Total Amount | AD2: Order Date
A3: Row Labels | B3: Sum of Quantity | C3: Sum of Total Amount | W3: F01 | X3: Non-Veg | Y3: {=_xlfn.SWITCH(W3,"F01","Biryani","F02","Puri","F03","Mutton Biryani","F04","Mutton Soup","F05","Veg Biryani","F06","Panner Biryani","F07","Mushroom Biryani")} -> Biryani | Z3: Dine-in | AA3: 1 | AB3: {=_xlfn.SWITCH(Z3,"DINE-IN","2000","TAKEAWAY","1000")} -> 2000 | AC3: =AA3*AB3 -> 2000 | AD3: 45728
A4: F01 | B4: 20 | C4: 34000 | W4: F02 | X4: Veg | Y4: {=_xlfn.SWITCH(W4,"F01","Biryani","F02","Puri","F03","Mutton Biryani","F04","Mutton Soup","F05","Veg Biryani","F06","Panner Biryani","F07","Mushroom Biryani")} -> Puri | Z4: Takeaway | AA4: 2 | AB4: {=_xlfn.SWITCH(Z4,"DINE-IN","2000","TAKEAWAY","1000")} -> 1000 | AC4: =AA4*AB4 -> 2000 | AD4: 45699
A5: Non-Veg | B5: 20 | C5: 34000 | W5: F03 | X5: Non-Veg | Y5: {=_xlfn.SWITCH(W5,"F01","Biryani","F02","Puri","F03","Mutton Biryani","F04","Mutton Soup","F05","Veg Biryani","F06","Panner Biryani","F07","Mushroom Biryani")} -> Mutton Biryani | Z5: Dine-in | AA5: 2 | AB5: {=_xlfn.SWITCH(Z5,"DINE-IN","2000","TAKEAWAY","1000")} -> 2000 | AC5: =AA5*AB5 -> 4000 | AD5: 45882
A6: Biryani | B6: 20 | C6: 34000 | W6: F04 | X6: Non-Veg | Y6: {=_xlfn.SWITCH(W6,"F01","Biryani","F02","Puri","F03","Mutton Biryani","F04","Mutton Soup","F05","Veg Biryani","F06","Panner Biryani","F07","Mushroom Biryani")} -> Mutton Soup | Z6: Dine-in | AA6: 3 | AB6: {=_xlfn.SWITCH(Z6,"DINE-IN","2000","TAKEAWAY","1000")} -> 2000 | AC6: =AA6*AB6 -> 6000 | AD6: 45727
A7: 1000 | B7: 6 | C7: 6000 | W7: F05 | X7: Veg | Y7: {=_xlfn.SWITCH(W7,"F01","Biryani","F02","Puri","F03","Mutton Biryani","F04","Mutton Soup","F05","Veg Biryani","F06","Panner Biryani","F07","Mushroom Biryani")} -> Veg Biryani | Z7: Takeaway | AA7: 1 | AB7: {=_xlfn.SWITCH(Z7,"DINE-IN","2000","TAKEAWAY","1000")} -> 1000 | AC7: =AA7*AB7 -> 1000 | AD7: 46003
A8: Takeaway | B8: 6 | C8: 6000 | W8: F06 | X8: Veg | Y8: {=_xlfn.SWITCH(W8,"F01","Biryani","F02","Puri","F03","Mutton Biryani","F04","Mutton Soup","F05","Veg Biryani","F06","Panner Biryani","F07","Mushroom Biryani")} -> Panner Biryani | Z8: Dine-in | AA8: 2 | AB8: {=_xlfn.SWITCH(Z8,"DINE-IN","2000","TAKEAWAY","1000")} -> 2000 | AC8: =AA8*AB8 -> 4000 | AD8: 45748
A9: 2000 | B9: 14 | C9: 28000 | W9: F07 | X9: Veg | Y9: {=_xlfn.SWITCH(W9,"F01","Biryani","F02","Puri","F03","Mutton Biryani","F04","Mutton Soup","F05","Veg Biryani","F06","Panner Biryani","F07","Mushroom Biryani")} -> Mushroom Biryani | Z9: Takeaway | AA9: 2 | AB9: {=_xlfn.SWITCH(Z9,"DINE-IN","2000","TAKEAWAY","1000")} -> 1000 | AC9: =AA9*AB9 -> 2000 | AD9: 45788
A10: Dine-in | B10: 14 | C10: 28000 | W10: F03 | X10: Non-Veg | Y10: {=_xlfn.SWITCH(W10,"F01","Biryani","F02","Puri","F03","Mutton Biryani","F04","Mutton Soup","F05","Veg Biryani","F06","Panner Biryani","F07","Mushroom Biryani")} -> Mutton Biryani | Z10: Takeaway | AA10: 4 | AB10: {=_xlfn.SWITCH(Z10,"DINE-IN","2000","TAKEAWAY","1000")} -> 1000 | AC10: =AA10*AB10 -> 4000 | AD10: 45911
A11: F02 | B11: 10 | C11: 18000 | W11: F04 | X11: Non-Veg | Y11: {=_xlfn.SWITCH(W11,"F01","Biryani","F02","Puri","F03","Mutton Biryani","F04","Mutton Soup","F05","Veg Biryani","F06","Panner Biryani","F07","Mushroom Biryani")} -> Mutton Soup | Z11: Dine-in | AA11: 2 | AB11: {=_xlfn.SWITCH(Z11,"DINE-IN","2000","TAKEAWAY","1000")} -> 2000 | AC11: =AA11*AB11 -> 4000 | AD11: 45873
A12: Veg | B12: 10 | C12: 18000 | W12: F05 | X12: Veg | Y12: {=_xlfn.SWITCH(W12,"F01","Biryani","F02","Puri","F03","Mutton Biryani","F04","Mutton Soup","F05","Veg Biryani","F06","Panner Biryani","F07","Mushroom Biryani")} -> Veg Biryani | Z12: Takeaway | AA12: 1 | AB12: {=_xlfn.SWITCH(Z12,"DINE-IN","2000","TAKEAWAY","1000")} -> 1000 | AC12: =AA12*AB12 -> 1000 | AD12: 45816
A13: Puri | B13: 10 | C13: 18000 | W13: F06 | X13: Veg | Y13: {=_xlfn.SWITCH(W13,"F01","Biryani","F02","Puri","F03","Mutton Biryani","F04","Mutton Soup","F05","Veg Biryani","F06","Panner Biryani","F07","Mushroom Biryani")} -> Panner Biryani | Z13: Dine-in | AA13: 2 | AB13: {=_xlfn.SWITCH(Z13,"DINE-IN","2000","TAKEAWAY","1000")} -> 2000 | AC13: =AA13*AB13 -> 4000 | AD13: 45728
A14: 1000 | B14: 2 | C14: 2000 | W14: F07 | X14: Veg | Y14: {=_xlfn.SWITCH(W14,"F01","Biryani","F02","Puri","F03","Mutton Biryani","F04","Mutton Soup","F05","Veg Biryani","F06","Panner Biryani","F07","Mushroom Biryani")} -> Mushroom Biryani | Z14: Takeaway | AA14: 1 | AB14: {=_xlfn.SWITCH(Z14,"DINE-IN","2000","TAKEAWAY","1000")} -> 1000 | AC14: =AA14*AB14 -> 1000 | AD14: 45699
A15: Takeaway | B15: 2 | C15: 2000 | W15: F01 | X15: Non-Veg | Y15: {=_xlfn.SWITCH(W15,"F01","Biryani","F02","Puri","F03","Mutton Biryani","F04","Mutton Soup","F05","Veg Biryani","F06","Panner Biryani","F07","Mushroom Biryani")} -> Biryani | Z15: Dine-in | AA15: 2 | AB15: {=_xlfn.SWITCH(Z15,"DINE-IN","2000","TAKEAWAY","1000")} -> 2000 | AC15: =AA15*AB15 -> 4000 | AD15: 45882
... A49: Grand Total | B49: 115 | C49: 167000 | W49: F05 | X49: Veg | Y49: {=_xlfn.SWITCH(W49,"F01","Biryani","F02","Puri","F03","Mutton Biryani","F04","Mutton Soup","F05","Veg Biryani","F06","Panner Biryani","F07","Mushroom Biryani")} -> Veg Biryani | Z49: Takeaway | AA49: 4 | AB49: {=_xlfn.SWITCH(Z49,"DINE-IN","2000","TAKEAWAY","1000")} -> 1000 | AC49: =AA49*AB49 -> 4000 | AD49: 45788
W50: F06 | X50: Veg | Y50: {=_xlfn.SWITCH(W50,"F01","Biryani","F02","Puri","F03","Mutton Biryani","F04","Mutton Soup","F05","Veg Biryani","F06","Panner Biryani","F07","Mushroom Biryani")} -> Panner Biryani | Z50: Takeaway | AA50: 2 | AB50: {=_xlfn.SWITCH(Z50,"DINE-IN","2000","TAKEAWAY","1000")} -> 1000 | AC50: =AA50*AB50 -> 2000 | AD50: 45911
W51: F01 | X51: Non-Veg | Y51: {=_xlfn.SWITCH(W51,"F01","Biryani","F02","Puri","F03","Mutton Biryani","F04","Mutton Soup","F05","Veg Biryani","F06","Panner Biryani","F07","Mushroom Biryani")} -> Biryani | Z51: Dine-in | AA51: 1 | AB51: {=_xlfn.SWITCH(Z51,"DINE-IN","2000","TAKEAWAY","1000")} -> 2000 | AC51: =AA51*AB51 -> 2000 | AD51: 45873
W52: F01 | X52: Non-Veg | Y52: {=_xlfn.SWITCH(W52,"F01","Biryani","F02","Puri","F03","Mutton Biryani","F04","Mutton Soup","F05","Veg Biryani","F06","Panner Biryani","F07","Mushroom Biryani")} -> Biryani | Z52: Takeaway | AA52: 2 | AB52: {=_xlfn.SWITCH(Z52,"DINE-IN","2000","TAKEAWAY","1000")} -> 1000 | AC52: =AA52*AB52 -> 2000 | AD52: 45816

Sheet Lookups
A1: Food ID | B1: Food Type | C1: Food Name | D1: Order Type | E1: Quantity | F1: Price | G1: Total Amount
A2: F01 | B2: Non-Veg | C2: {=_xlfn.SWITCH(A2,"F01","Biryani","F02","Puri","F03","Mutton Biryani","F04","Mutton Soup","F05","Veg Biryani","F06","Panner Biryani","F07","Mushroom Biryani")} -> Biryani | D2: Dine-in | E2: 1 | F2: {=_xlfn.SWITCH(D2,"DINE-IN","2000","TAKEAWAY","1000")} -> 2000 | G2: =E2*F2 -> 2000
A3: F02 | B3: Veg | C3: {=_xlfn.SWITCH(A3,"F01","Biryani","F02","Puri","F03","Mutton Biryani","F04","Mutton Soup","F05","Veg Biryani","F06","Panner Biryani","F07","Mushroom Biryani")} -> Puri | D3: Takeaway | E3: 2 | F3: {=_xlfn.SWITCH(D3,"DINE-IN","2000","TAKEAWAY","1000")} -> 1000 | G3: =E3*F3 -> 2000
A4: F03 | B4: Non-Veg | C4: {=_xlfn.SWITCH(A4,"F01","Biryani","F02","Puri","F03","Mutton Biryani","F04","Mutton Soup","F05","Veg Biryani","F06","Panner Biryani","F07","Mushroom Biryani")} -> Mutton Biryani | D4: Dine-in | E4: 2 | F4: {=_xlfn.SWITCH(D4,"DINE-IN","2000","TAKEAWAY","1000")} -> 2000 | G4: =E4*F4 -> 4000
A5: F04 | B5: Non-Veg | C5: {=_xlfn.SWITCH(A5,"F01","Biryani","F02","Puri","F03","Mutton Biryani","F04","Mutton Soup","F05","Veg Biryani","F06","Panner Biryani","F07","Mushroom Biryani")} -> Mutton Soup | D5: Dine-in | E5: 3 | F5: {=_xlfn.SWITCH(D5,"DINE-IN","2000","TAKEAWAY","1000")} -> 2000 | G5: =E5*F5 -> 6000
A6: F05 | B6: Veg | C6: {=_xlfn.SWITCH(A6,"F01","Biryani","F02","Puri","F03","Mutton Biryani","F04","Mutton Soup","F05","Veg Biryani","F06","Panner Biryani","F07","Mushroom Biryani")} -> Veg Biryani | D6: Takeaway | E6: 1 | F6: {=_xlfn.SWITCH(D6,"DINE-IN","2000","TAKEAWAY","1000")} -> 1000 | G6: =E6*F6 -> 1000 | J6: Food Details
A7: F06 | B7: Veg | C7: {=_xlfn.SWITCH(A7,"F01","Biryani","F02","Puri","F03","Mutton Biryani","F04","Mutton Soup","F05","Veg Biryani","F06","Panner Biryani","F07","Mushroom Biryani")} -> Panner Biryani | D7: Dine-in | E7: 2 | F7: {=_xlfn.SWITCH(D7,"DINE-IN","2000","TAKEAWAY","1000")} -> 2000 | G7: =E7*F7 -> 4000 | J7: Food ID | K7: Food Type | L7: Food Name | M7: Total Amount
A8: F07 | B8: Veg | C8: {=_xlfn.SWITCH(A8,"F01","Biryani","F02","Puri","F03","Mutton Biryani","F04","Mutton Soup","F05","Veg Biryani","F06","Panner Biryani","F07","Mushroom Biryani")} -> Mushroom Biryani | D8: Takeaway | E8: 2 | F8: {=_xlfn.SWITCH(D8,"DINE-IN","2000","TAKEAWAY","1000")} -> 1000 | G8: =E8*F8 -> 2000 | J8: F01 | K8: {=VLOOKUP(J8,A1:G51,{2,3,7},0)} -> Non-Veg | L8: Biryani | M8: 2000
A9: F03 | B9: Non-Veg | C9: {=_xlfn.SWITCH(A9,"F01","Biryani","F02","Puri","F03","Mutton Biryani","F04","Mutton Soup","F05","Veg Biryani","F06","Panner Biryani","F07","Mushroom Biryani")} -> Mutton Biryani | D9: Takeaway | E9: 4 | F9: {=_xlfn.SWITCH(D9,"DINE-IN","2000","TAKEAWAY","1000")} -> 1000 | G9: =E9*F9 -> 4000 | J9: F03 | K9: {=VLOOKUP(J9,A1:G51,{2,3,7},0)} -> Non-Veg | L9: Mutton Biryani | M9: 4000
A10: F04 | B10: Non-Veg | C10: {=_xlfn.SWITCH(A10,"F01","Biryani","F02","Puri","F03","Mutton Biryani","F04","Mutton Soup","F05","Veg Biryani","F06","Panner Biryani","F07","Mushroom Biryani")} -> Mutton Soup | D10: Dine-in | E10: 2 | F10: {=_xlfn.SWITCH(D10,"DINE-IN","2000","TAKEAWAY","1000")} -> 2000 | G10: =E10*F10 -> 4000
A11: F05 | B11: Veg | C11: {=_xlfn.SWITCH(A11,"F01","Biryani","F02","Puri","F03","Mutton Biryani","F04","Mutton Soup","F05","Veg Biryani","F06","Panner Biryani","F07","Mushroom Biryani")} -> Veg Biryani | D11: Takeaway | E11: 1 | F11: {=_xlfn.SWITCH(D11,"DINE-IN","2000","TAKEAWAY","1000")} -> 1000 | G11: =E11*F11 -> 1000
A12: F06 | B12: Veg | C12: {=_xlfn.SWITCH(A12,"F01","Biryani","F02","Puri","F03","Mutton Biryani","F04","Mutton Soup","F05","Veg Biryani","F06","Panner Biryani","F07","Mushroom Biryani")} -> Panner Biryani | D12: Dine-in | E12: 2 | F12: {=_xlfn.SWITCH(D12,"DINE-IN","2000","TAKEAWAY","1000")} -> 2000 | G12: =E12*F12 -> 4000
A13: F07 | B13: Veg | C13: {=_xlfn.SWITCH(A13,"F01","Biryani","F02","Puri","F03","Mutton Biryani","F04","Mutton Soup","F05","Veg Biryani","F06","Panner Biryani","F07","Mushroom Biryani")} -> Mushroom Biryani | D13: Takeaway | E13: 1 | F13: {=_xlfn.SWITCH(D13,"DINE-IN","2000","TAKEAWAY","1000")} -> 1000 | G13: =E13*F13 -> 1000
A14: F01 | B14: Non-Veg | C14: {=_xlfn.SWITCH(A14,"F01","Biryani","F02","Puri","F03","Mutton Biryani","F04","Mutton Soup","F05","Veg Biryani","F06","Panner Biryani","F07","Mushroom Biryani")} -> Biryani | D14: Dine-in | E14: 2 | F14: {=_xlfn.SWITCH(D14,"DINE-IN","2000","TAKEAWAY","1000")} -> 2000 | G14: =E14*F14 -> 4000
A15: F02 | B15: Veg | C15: {=_xlfn.SWITCH(A15,"F01","Biryani","F02","Puri","F03","Mutton Biryani","F04","Mutton Soup","F05","Veg Biryani","F06","Panner Biryani","F07","Mushroom Biryani")} -> Puri | D15: Dine-in | E15: 1 | F15: {=_xlfn.SWITCH(D15,"DINE-IN","2000","TAKEAWAY","1000")} -> 2000 | G15: =E15*F15 -> 2000 | J15: Food Details
A16: F03 | B16: Non-Veg | C16: {=_xlfn.SWITCH(A16,"F01","Biryani","F02","Puri","F03","Mutton Biryani","F04","Mutton Soup","F05","Veg Biryani","F06","Panner Biryani","F07","Mushroom Biryani")} -> Mutton Biryani | D16: Takeaway | E16: 2 | F16: {=_xlfn.SWITCH(D16,"DINE-IN","2000","TAKEAWAY","1000")} -> 1000 | G16: =E16*F16 -> 2000 | J16: Food ID | K16: Food Type | L16: Food Name | M16: Order Type | N16: Quantity | O16: Price | P16: Total Amount
A17: F04 | B17: Non-Veg | C17: {=_xlfn.SWITCH(A17,"F01","Biryani","F02","Puri","F03","Mutton Biryani","F04","Mutton Soup","F05","Veg Biryani","F06","Panner Biryani","F07","Mushroom Biryani")} -> Mutton Soup | D17: Dine-in | E17: 2 | F17: {=_xlfn.SWITCH(D17,"DINE-IN","2000","TAKEAWAY","1000")} -> 2000 | G17: =E17*F17 -> 4000 | J17: F02 | K17: {=_xlfn.XLOOKUP(J17,A1:A51,B1:G51)} -> Veg | L17: Puri | M17: Takeaway | N17: 2 | O17: 1000 | P17: 2000
A18: F05 | B18: Veg | C18: {=_xlfn.SWITCH(A18,"F01","Biryani","F02","Puri","F03","Mutton Biryani","F04","Mutton Soup","F05","Veg Biryani","F06","Panner Biryani","F07","Mushroom Biryani")} -> Veg Biryani | D18: Takeaway | E18: 3 | F18: {=_xlfn.SWITCH(D18,"DINE-IN","2000","TAKEAWAY","1000")} -> 1000 | G18: =E18*F18 -> 3000 | J18: F04 | K18: {=_xlfn.XLOOKUP(J18,A1:A51,B1:G51)} -> Non-Veg | L18: Mutton Soup | M18: Dine-in | N18: 3 | O18: 2000 | P18: 6000
A19: F06 | B19: Veg | C19: {=_xlfn.SWITCH(A19,"F01","Biryani","F02","Puri","F03","Mutton Biryani","F04","Mutton Soup","F05","Veg Biryani","F06","Panner Biryani","F07","Mushroom Biryani")} -> Panner Biryani | D19: Takeaway | E19: 1 | F19: {=_xlfn.SWITCH(D19,"DINE-IN","2000","TAKEAWAY","1000")} -> 1000 | G19: =E19*F19 -> 1000
A20: F07 | B20: Veg | C20: {=_xlfn.SWITCH(A20,"F01","Biryani","F02","Puri","F03","Mutton Biryani","F04","Mutton Soup","F05","Veg Biryani","F06","Panner Biryani","F07","Mushroom Biryani")} -> Mushroom Biryani | D20: Dine-in | E20: 2 | F20: {=_xlfn.SWITCH(D20,"DINE-IN","2000","TAKEAWAY","1000")} -> 2000 | G20: =E20*F20 -> 4000
A21: F05 | B21: Veg | C21: {=_xlfn.SWITCH(A21,"F01","Biryani","F02","Puri","F03","Mutton Biryani","F04","Mutton Soup","F05","Veg Biryani","F06","Panner Biryani","F07","Mushroom Biryani")} -> Veg Biryani | D21: Takeaway | E21: 3 | F21: {=_xlfn.SWITCH(D21,"DINE-IN","2000","TAKEAWAY","1000")} -> 1000 | G21: =E21*F21 -> 3000
A22: F06 | B22: Veg | C22: {=_xlfn.SWITCH(A22,"F01","Biryani","F02","Puri","F03","Mutton Biryani","F04","Mutton Soup","F05","Veg Biryani","F06","Panner Biryani","F07","Mushroom Biryani")} -> Panner Biryani | D22: Dine-in | E22: 1 | F22: {=_xlfn.SWITCH(D22,"DINE-IN","2000","TAKEAWAY","1000")} -> 2000 | G22: =E22*F22 -> 2000
A23: F07 | B23: Veg | C23: {=_xlfn.SWITCH(A23,"F01","Biryani","F02","Puri","F03","Mutton Biryani","F04","Mutton Soup","F05","Veg Biryani","F06","Panner Biryani","F07","Mushroom Biryani")} -> Mushroom Biryani | D23: Takeaway | E23: 1 | F23: {=_xlfn.SWITCH(D23,"DINE-IN","2000","TAKEAWAY","1000")} -> 1000 | G23: =E23*F23 -> 1000
A24: F01 | B24: Non-Veg | C24: {=_xlfn.SWITCH(A24,"F01","Biryani","F02","Puri","F03","Mutton Biryani","F04","Mutton Soup","F05","Veg Biryani","F06","Panner Biryani","F07","Mushroom Biryani")} -> Biryani | D24: Dine-in | E24: 3 | F24: {=_xlfn.SWITCH(D24,"DINE-IN","2000","TAKEAWAY","1000")} -> 2000 | G24: =E24*F24 -> 6000
A25: F02 | B25: Veg | C25: {=_xlfn.SWITCH(A25,"F01","Biryani","F02","Puri","F03","Mutton Biryani","F04","Mutton Soup","F05","Veg Biryani","F06","Panner Biryani","F07","Mushroom Biryani")} -> Puri | D25: Dine-in | E25: 2 | F25: {=_xlfn.SWITCH(D25,"DINE-IN","2000","TAKEAWAY","1000")} -> 2000 | G25: =E25*F25 -> 4000
A26: F03 | B26: Non-Veg | C26: {=_xlfn.SWITCH(A26,"F01","Biryani","F02","Puri","F03","Mutton Biryani","F04","Mutton Soup","F05","Veg Biryani","F06","Panner Biryani","F07","Mushroom Biryani")} -> Mutton Biryani | D26: Takeaway | E26: 3 | F26: {=_xlfn.SWITCH(D26,"DINE-IN","2000","TAKEAWAY","1000")} -> 1000 | G26: =E26*F26 -> 3000
A27: F04 | B27: Non-Veg | C27: {=_xlfn.SWITCH(A27,"F01","Biryani","F02","Puri","F03","Mutton Biryani","F04","Mutton Soup","F05","Veg Biryani","F06","Panner Biryani","F07","Mushroom Biryani")} -> Mutton Soup | D27: Dine-in | E27: 1 | F27: {=_xlfn.SWITCH(D27,"DINE-IN","2000","TAKEAWAY","1000")} -> 2000 | G27: =E27*F27 -> 2000
A28: F05 | B28: Veg | C28: {=_xlfn.SWITCH(A28,"F01","Biryani","F02","Puri","F03","Mutton Biryani","F04","Mutton Soup","F05","Veg Biryani","F06","Panner Biryani","F07","Mushroom Biryani")} -> Veg Biryani | D28: Takeaway | E28: 4 | F28: {=_xlfn.SWITCH(D28,"DINE-IN","2000","TAKEAWAY","1000")} -> 1000 | G28: =E28*F28 -> 4000
A29: F06 | B29: Veg | C29: {=_xlfn.SWITCH(A29,"F01","Biryani","F02","Puri","F03","Mutton Biryani","F04","Mutton Soup","F05","Veg Biryani","F06","Panner Biryani","F07","Mushroom Biryani")} -> Panner Biryani | D29: Takeaway | E29: 4 | F29: {=_xlfn.SWITCH(D29,"DINE-IN","2000","TAKEAWAY","1000")} -> 1000 | G29: =E29*F29 -> 4000
A30: F07 | B30: Veg | C30: {=_xlfn.SWITCH(A30,"F01","Biryani","F02","Puri","F03","Mutton Biryani","F04","Mutton Soup","F05","Veg Biryani","F06","Panner Biryani","F07","Mushroom Biryani")} -> Mushroom Biryani | D30: Dine-in | E30: 3 | F30: {=_xlfn.SWITCH(D30,"DINE-IN","2000","TAKEAWAY","1000")} -> 2000 | G30: =E30*F30 -> 6000
... A51: F01 | B51: Non-Veg | C51: {=_xlfn.SWITCH(A51,"F01","Biryani","F02","Puri","F03","Mutton Biryani","F04","Mutton Soup","F05","Veg Biryani","F06","Panner Biryani","F07","Mushroom Biryani")} -> Biryani | D51: Takeaway | E51: 2 | F51: {=_xlfn.SWITCH(D51,"DINE-IN","2000","TAKEAWAY","1000")} -> 1000 | G51: =E51*F51 -> 2000

Sheet Total Bill
B2: Coustmer Total Bill
A3: S.no | B3: Coustmer ID | C3: Room No | D3: Floor No | E3: Check-Out-Date | F3: Room Amount | G3: Food Amount | H3: Total Bill
A4: 1 | B4: ='Coustmer Details'!B4 -> C001 | C4: ='Room Details'!C4 -> R102 | D4: ='Room Details'!E4 -> 1 | E4: ='Room Details'!I4 -> 45730 | F4: ='Room Details'!G4 -> 2000 | G4: ='Food Details'!K4 -> 500 | H4: =F4+G4 -> 2500
A5: 2 | B5: ='Coustmer Details'!B5 -> C002 | C5: ='Room Details'!C5 -> R103 | D5: ='Room Details'!E5 -> 3 | E5: ='Room Details'!I5 -> 45699 | F5: ='Room Details'!G5 -> 4000 | G5: ='Food Details'!K5 -> 200 | H5: =F5+G5 -> 4200
A6: 3 | B6: ='Coustmer Details'!B6 -> C003 | C6: ='Room Details'!C6 -> R104 | D6: ='Room Details'!E6 -> 2 | E6: ='Room Details'!I6 -> 45883 | F6: ='Room Details'!G6 -> 5000 | G6: ='Food Details'!K6 -> 1400 | H6: =F6+G6 -> 6400
A7: 4 | B7: ='Coustmer Details'!B7 -> C004 | C7: ='Room Details'!C7 -> R105 | D7: ='Room Details'!E7 -> 1 | E7: ='Room Details'!I7 -> 45729 | F7: ='Room Details'!G7 -> 6000 | G7: ='Food Details'!K7 -> 900 | H7: =F7+G7 -> 6900 | L7: Total Bill
A8: 5 | B8: ='Coustmer Details'!B8 -> C005 | C8: ='Room Details'!C8 -> R106 | D8: ='Room Details'!E8 -> 4 | E8: ='Room Details'!I8 -> 46005 | F8: ='Room Details'!G8 -> 2000 | G8: ='Food Details'!K8 -> 500 | H8: =F8+G8 -> 2500 | L8: Coustmer ID | M8: Room No | N8: Floor No | O8: Total Bill
A9: 6 | B9: ='Coustmer Details'!B9 -> C006 | C9: ='Room Details'!C9 -> R107 | D9: ='Room Details'!E9 -> 2 | E9: ='Room Details'!I9 -> 45748 | F9: ='Room Details'!G9 -> 2000 | G9: ='Food Details'!K9 -> 700 | H9: =F9+G9 -> 2700 | L9: C003 | M9: {=VLOOKUP(L9,B3:H53,{2,3,7},0)} -> R104 | N9: 2 | O9: 6400
A10: 7 | B10: ='Coustmer Details'!B10 -> C007 | C10: ='Room Details'!C10 -> R108 | D10: ='Room Details'!E10 -> 2 | E10: ='Room Details'!I10 -> 45789 | F10: ='Room Details'!G10 -> 4000 | G10: ='Food Details'!K10 -> 800 | H10: =F10+G10 -> 4800 | L10: C007 | M10: {=VLOOKUP(L10,B3:H53,{2,3,7},0)} -> R108 | N10: 2 | O10: 4800
A11: 8 | B11: ='Coustmer Details'!B11 -> C008 | C11: ='Room Details'!C11 -> R109 | D11: ='Room Details'!E11 -> 1 | E11: ='Room Details'!I11 -> 45911 | F11: ='Room Details'!G11 -> 4000 | G11: ='Food Details'!K11 -> 2800 | H11: =F11+G11 -> 6800
A12: 9 | B12: ='Coustmer Details'!B12 -> C009 | C12: ='Room Details'!C12 -> R110 | D12: ='Room Details'!E12 -> 3 | E12: ='Room Details'!I12 -> 45874 | F12: ='Room Details'!G12 -> 2000 | G12: ='Food Details'!K12 -> 600 | H12: =F12+G12 -> 2600
A13: 10 | B13: ='Coustmer Details'!B13 -> C010 | C13: ='Room Details'!C13 -> R111 | D13: ='Room Details'!E13 -> 2 | E13: ='Room Details'!I13 -> 45817 | F13: ='Room Details'!G13 -> 4000 | G13: ='Food Details'!K13 -> 500 | H13: =F13+G13 -> 4500
A14: 11 | B14: ='Coustmer Details'!B14 -> C011 | C14: ='Room Details'!C14 -> R112 | D14: ='Room Details'!E14 -> 1 | E14: ='Room Details'!I14 -> 45730 | F14: ='Room Details'!G14 -> 5000 | G14: ='Food Details'!K14 -> 700 | H14: =F14+G14 -> 5700
A15: 12 | B15: ='Coustmer Details'!B15 -> C012 | C15: ='Room Details'!C15 -> R113 | D15: ='Room Details'!E15 -> 4 | E15: ='Room Details'!I15 -> 45699 | F15: ='Room Details'!G15 -> 6000 | G15: ='Food Details'!K15 -> 400 | H15: =F15+G15 -> 6400
A16: 13 | B16: ='Coustmer Details'!B16 -> C013 | C16: ='Room Details'!C16 -> R114 | D16: ='Room Details'!E16 -> 2 | E16: ='Room Details'!I16 -> 45883 | F16: ='Room Details'!G16 -> 2000 | G16: ='Food Details'!K16 -> 1000 | H16: =F16+G16 -> 3000
A17: 14 | B17: ='Coustmer Details'!B17 -> C014 | C17: ='Room Details'!C17 -> R115 | D17: ='Room Details'!E17 -> 2 | E17: ='Room Details'!I17 -> 45729 | F17: ='Room Details'!G17 -> 2000 | G17: ='Food Details'!K17 -> 100 | H17: =F17+G17 -> 2100
A18: 15 | B18: ='Coustmer Details'!B18 -> C015 | C18: ='Room Details'!C18 -> R116 | D18: ='Room Details'!E18 -> 1 | E18: ='Room Details'!I18 -> 46005 | F18: ='Room Details'!G18 -> 4000 | G18: ='Food Details'!K18 -> 1400 | H18: =F18+G18 -> 5400
A19: 16 | B19: ='Coustmer Details'!B19 -> C016 | C19: ='Room Details'!C19 -> R117 | D19: ='Room Details'!E19 -> 3 | E19: ='Room Details'!I19 -> 45748 | F19: ='Room Details'!G19 -> 4000 | G19: ='Food Details'!K19 -> 600 | H19: =F19+G19 -> 4600 | L19: Total Bill
A20: 17 | B20: ='Coustmer Details'!B20 -> C017 | C20: ='Room Details'!C20 -> R118 | D20: ='Room Details'!E20 -> 2 | E20: ='Room Details'!I20 -> 45789 | F20: ='Room Details'!G20 -> 2000 | G20: ='Food Details'!K20 -> 1500 | H20: =F20+G20 -> 3500 | L20: Coustmer ID | M20: Room No | N20: Floor No | O20: Check-out-Date | P20: Room Amount | Q20: Food Amount | R20: Total Bill
A21: 18 | B21: ='Coustmer Details'!B21 -> C018 | C21: ='Room Details'!C21 -> R119 | D21: ='Room Details'!E21 -> 1 | E21: ='Room Details'!I21 -> 45911 | F21: ='Room Details'!G21 -> 4000 | G21: ='Food Details'!K21 -> 350 | H21: =F21+G21 -> 4350 | L21: C010 | M21: {=_xlfn.XLOOKUP(L21,B3:B53,C3:H53)} -> R111 | N21: 2 | O21: 45817 | P21: 4000 | Q21: 500 | R21: 4500
A22: 19 | B22: ='Coustmer Details'!B22 -> C019 | C22: ='Room Details'!C22 -> R120 | D22: ='Room Details'!E22 -> 4 | E22: ='Room Details'!I22 -> 45874 | F22: ='Room Details'!G22 -> 5000 | G22: ='Food Details'!K22 -> 800 | H22: =F22+G22 -> 5800 | L22: C008 | M22: {=_xlfn.XLOOKUP(L22,B3:B53,C3:H53)} -> R109 | N22: 1 | O22: 45911 | P22: 4000 | Q22: 2800 | R22: 6800
A23: 20 | B23: ='Coustmer Details'!B23 -> C020 | C23: ='Room Details'!C23 -> R121 | D23: ='Room Details'!E23 -> 2 | E23: ='Room Details'!I23 -> 45817 | F23: ='Room Details'!G23 -> 6000 | G23: ='Food Details'!K23 -> 1500 | H23: =F23+G23 -> 7500
A24: 21 | B24: ='Coustmer Details'!B24 -> C021 | C24: ='Room Details'!C24 -> R122 | D24: ='Room Details'!E24 -> 2 | E24: ='Room Details'!I24 -> 45730 | F24: ='Room Details'!G24 -> 2000 | G24: ='Food Details'!K24 -> 350 | H24: =F24+G24 -> 2350
A25: 22 | B25: ='Coustmer Details'!B25 -> C022 | C25: ='Room Details'!C25 -> R123 | D25: ='Room Details'!E25 -> 1 | E25: ='Room Details'!I25 -> 45699 | F25: ='Room Details'!G25 -> 2000 | G25: ='Food Details'!K25 -> 400 | H25: =F25+G25 -> 2400
A26: 23 | B26: ='Coustmer Details'!B26 -> C023 | C26: ='Room Details'!C26 -> R124 | D26: ='Room Details'!E26 -> 3 | E26: ='Room Details'!I26 -> 45883 | F26: ='Room Details'!G26 -> 4000 | G26: ='Food Details'!K26 -> 1500 | H26: =F26+G26 -> 5500
A27: 24 | B27: ='Coustmer Details'!B27 -> C024 | C27: ='Room Details'!C27 -> R125 | D27: ='Room Details'!E27 -> 2 | E27: ='Room Details'!I27 -> 45729 | F27: ='Room Details'!G27 -> 4000 | G27: ='Food Details'!K27 -> 200 | H27: =F27+G27 -> 4200
A28: 25 | B28: ='Coustmer Details'!B28 -> C025 | C28: ='Room Details'!C28 -> R126 | D28: ='Room Details'!E28 -> 1 | E28: ='Room Details'!I28 -> 46005 | F28: ='Room Details'!G28 -> 2000 | G28: ='Food Details'!K28 -> 2100 | H28: =F28+G28 -> 4100
A29: 26 | B29: ='Coustmer Details'!B29 -> C026 | C29: ='Room Details'!C29 -> R127 | D29: ='Room Details'!E29 -> 4 | E29: ='Room Details'!I29 -> 45748 | F29: ='Room Details'!G29 -> 4000 | G29: ='Food Details'!K29 -> 300 | H29: =F29+G29 -> 4300
A30: 27 | B30: ='Coustmer Details'!B30 -> C027 | C30: ='Room Details'!C30 -> R128 | D30: ='Room Details'!E30 -> 2 | E30: ='Room Details'!I30 -> 45789 | F30: ='Room Details'!G30 -> 5000 | G30: ='Food Details'!K30 -> 2000 | H30: =F30+G30 -> 7000
A31: 28 | B31: ='Coustmer Details'!B31 -> C028 | C31: ='Room Details'!C31 -> R129 | D31: ='Room Details'!E31 -> 2 | E31: ='Room Details'!I31 -> 45911 | F31: ='Room Details'!G31 -> 6000 | G31: ='Food Details'!K31 -> 1400 | H31: =F31+G31 -> 7400
A32: 29 | B32: ='Coustmer Details'!B32 -> C029 | C32: ='Room Details'!C32 -> R130 | D32: ='Room Details'!E32 -> 4 | E32: ='Room Details'!I32 -> 45874 | F32: ='Room Details'!G32 -> 2000 | G32: ='Food Details'!K32 -> 1200 | H32: =F32+G32 -> 3200
